Workbook

Sheet README
B1: TA3HRJ Koaksiyel Kablo Veritabanı
B2: Sürüm 1.0 · 2026-10-09 · 65 kablo · 1126 zayıflama noktası · 775 güç noktası · 53 kaynak belge (PDF/metin kopyaları 'kaynaklar' klasöründe)
B4: AMAÇ
B5: Her değeri bir datasheet'e bağlanmış, hesapları formülle yapılan ve ileride bir programa veritabanı olarak aktarılabilecek koaksiyel kablo tablosu. Orijinal elle hazırlanmış tablo Legacy_* sayfalarında korunur ve yeni verilerle karşılaştırılır.
B7: SAYFALAR
B8: Ham_Bands - Rapor: her kablo için amatör bantlarında dB/100 m ve dB/100 ft. Cables sayfasına eklenen kablo otomatik görünür (100 satıra kadar).
B9: Graph - Seçilen en fazla 8 kablonun 1-10000 MHz log-log zayıflama eğrisi (sarı hücrelerden seçim).
B10: Calculator - Kablo, frekans, uzunluk, güç ve SWR girin: kayıp, antene ulaşan güç, güç sınırı, dalga boyu. Altta tüm kabloların karşılaştırması.
B11: Cables - Kablo ana tablosu (bir satır = bir ürün). Elektriksel, mekanik, güç ve uygunluk parametreleri. Gri başlıklı sütunlar formüldür.
B12: Attenuation - Zayıflama noktaları (bir satır = bir datasheet değeri). Değer datasheet'te yazdığı birimde girilir, dB/100 m'ye formülle çevrilir.
B13: Power - Ortalama (CW) güç taşıma noktaları, datasheet'te yazdığı birimde.
B14: Sources - Kaynak belgeler: URL, revizyon, erişim tarihi ve 'kaynaklar' klasöründeki arşiv PDF'i.
... B43: Eski tablo: 60 satırın 59'u bir kabloyla eşlendi. 'RG58 CellFoil (9006)' için yayımlanmış veri bulunamadı. Aynı kablonun tekrarları (ör. 1/2" LDF ve 1/2" HELIAX) aynı cable_id'ye bağlandı. Bant aralığı dışında kalan eski değerler Legacy_Points'te renkli işaretlidir.

Sheet Ham_Bands
A1: Koaksiyel kablo zayıflaması - amatör bantları
A2: Değerler datasheet noktaları arasında log-log interpolasyonla hesaplanır. İtalik gri hücreler datasheet frekans aralığı dışındadır (ekstrapolasyon). En yüksek veri frekansının 2 katından yukarısı gösterilmez. Renk ölçeği her bantta kablolar arası karşılaştırmadır (yeşil = düşük kayıp).
J3: dB / 100 m | W3: dB / 100 ft (30.48 m)
J4: 160 m | K4: 80 m | L4: 40 m | M4: 20 m | N4: 15 m | O4: 10 m | P4: 6 m | Q4: 2 m | R4: 70 cm | S4: 23 cm | T4: 13 cm | U4: 6 cm | W4: 160 m | X4: 80 m | Y4: 40 m | Z4: 20 m | AA4: 15 m | AB4: 10 m | AC4: 6 m | AD4: 2 m | AE4: 70 cm | AF4: 23 cm | AG4: 13 cm | AH4: 6 cm
A5: cable_id | B5: Kablo | C5: Z0 (Ω) | D5: Çap (mm) | E5: VF | F5: Veri min (MHz) | G5: Veri maks (MHz) | H5: r0 | I5: n | J5: 1.8 | K5: 3.5 | L5: 7 | M5: 14 | N5: 21 | O5: 28 | P5: 50 | Q5: 144 | R5: 432 | S5: 1296 | T5: 2400 | U5: 5760 | W5: 1.8 | X5: 3.5 | Y5: 7 | Z5: 14 | AA5: 21 | AB5: 28 | AC5: 50 | AD5: 144 | AE5: 432 | AF5: 1296 | AG5: 2400 | AH5: 5760
A6: =IF(ROWS($A$6:A6)>COUNTA(Cables!$A:$A)-1,"",INDEX(Cables!$A:$A,ROWS($A$6:A6)+1)) -> BEL-83265 | B6: =IF($A6="","",IF(INDEX(Cables!$B:$B,MATCH($A6,Cables!$A:$A,0))="","",INDEX(Cables!$B:$B,MATCH($A6,Cables!$A:$A,0)))) -> Belden 83265 (RG-178) | C6: =IF($A6="","",IF(INDEX(Cables!$F:$F,MATCH($A6,Cables!$A:$A,0))="","",INDEX(Cables!$F:$F,MATCH($A6,Cables!$A:$A,0)))) -> 50 | D6: =IF($A6="","",IF(INDEX(Cables!$H:$H,MATCH($A6,Cables!$A:$A,0))="","",INDEX(Cables!$H:$H,MATCH($A6,Cables!$A:$A,0)))) -> 1.8 | E6: =IF($A6="","",IF(INDEX(Cables!$Q:$Q,MATCH($A6,Cables!$A:$A,0))="","",INDEX(Cables!$Q:$Q,MATCH($A6,Cables!$A:$A,0)))) -> 0.7 | F6: =IF($A6="","",IF(INDEX(Cables!$AQ:$AQ,MATCH($A6,Cables!$A:$A,0))="","",INDEX(Cables!$AQ:$AQ,MATCH($A6,Cables!$A:$A,0)))) -> 1 | G6: =IF($A6="","",IF(INDEX(Cables!$AR:$AR,MATCH($A6,Cables!$A:$A,0))="","",INDEX(Cables!$AR:$AR,MATCH($A6,Cables!$A:$A,0)))) -> 1000 | H6: =IF($A6="","",IF(INDEX(Cables!$AO:$AO,MATCH($A6,Cables!$A:$A,0))="","",INDEX(Cables!$AO:$AO,MATCH($A6,Cables!$A:$A,0)))) -> 2 | I6: =IF($A6="","",IF(INDEX(Cables!$AP:$AP,MATCH($A6,Cables!$A:$A,0))="","",INDEX(Cables!$AP:$AP,MATCH($A6,Cables!$A:$A,0)))) -> 9 | J6: =IF($A6="","",IF(J$5>2*$G6,"",EXP(FORECAST(LN(J$5),INDEX(Attenuation!$K:$K,($H6-1+MIN(MAX(IFERROR(MATCH(LN(J$5),INDEX(Attenuation!$J:$J,$H6):INDEX(Attenuation!$J:$J,$H6+$I6-1),1),1),1),$I6-1))):INDEX(Attenuation!$K:$K,($H6-1+MIN(MAX(IFERROR(MATCH(LN(J$5),INDEX(Attenuation!$J:$J,$H6):INDEX(Attenuation!$J:$J,$H6+$I6-1),1),1),1),$I6-1))+1),INDEX(Attenuation!$J:$J,($H6-1+MIN(MAX(IFERROR(MATCH(LN(J$5),INDEX(Attenuation!$J:$J,$H6):INDEX(Attenuation!$J:$J,$H6+$I6-1),1),1),1),$I6-1))):INDEX(Attenuation!$J:$J,($H6-1+MIN(MAX(IFERROR(MATCH(LN(J$5),INDEX(Attenuation!$J:$J,$H6):INDEX(Attenuation!$J:$J,$H6+$I6-1),1),1),1),$I6-1))+1))))) -> 10.375736 | K6: =IF($A6="","",IF(K$5>2*$G6,"",EXP(FORECAST(LN(K$5),INDEX(Attenuation!$K:$K,($H6-1+MIN(MAX(IFERROR(MATCH(LN(K$5),INDEX(Attenuation!$J:$J,$H6):INDEX(Attenuation!$J:$J,$H6+$I6-1),1),1),1),$I6-1))):INDEX(Attenuation!$K:$K,($H6-1+MIN(MAX(IFERROR(MATCH(LN(K$5),INDEX(Attenuation!$J:$J,$H6):INDEX(Attenuation!$J:$J,$H6+$I6-1),1),1),1),$I6-1))+1),INDEX(Attenuation!$J:$J,($H6-1+MIN(MAX(IFERROR(MATCH(LN(K$5),INDEX(Attenuation!$J:$J,$H6):INDEX(Attenuation!$J:$J,$H6+$I6-1),1),1),1),$I6-1))):INDEX(Attenuation!$J:$J,($H6-1+MIN(MAX(IFERROR(MATCH(LN(K$5),INDEX(Attenuation!$J:$J,$H6):INDEX(Attenuation!$J:$J,$H6+$I6-1),1),1),1),$I6-1))+1))))) -> 12.949406 | L6: =IF($A6="","",IF(L$5>2*$G6,"",EXP(FORECAST(LN(L$5),INDEX(Attenuation!$K:$K,($H6-1+MIN(MAX(IFERROR(MATCH(LN(L$5),INDEX(Attenuation!$J:$J,$H6):INDEX(Attenuation!$J:$J,$H6+$I6-1),1),1),1),$I6-1))):INDEX(Attenuation!$K:$K,($H6-1+MIN(MAX(IFERROR(MATCH(LN(L$5),INDEX(Attenuation!$J:$J,$H6):INDEX(Attenuation!$J:$J,$H6+$I6-1),1),1),1),$I6-1))+1),INDEX(Attenuation!$J:$J,($H6-1+MIN(MAX(IFERROR(MATCH(LN(L$5),INDEX(Attenuation!$J:$J,$H6):INDEX(Attenuation!$J:$J,$H6+$I6-1),1),1),1),$I6-1))):INDEX(Attenuation!$J:$J,($H6-1+MIN(MAX(IFERROR(MATCH(LN(L$5),INDEX(Attenuation!$J:$J,$H6):INDEX(Attenuation!$J:$J,$H6+$I6-1),1),1),1),$I6-1))+1))))) -> 16.313887 | M6: =IF($A6="","",IF(M$5>2*$G6,"",EXP(FORECAST(LN(M$5),INDEX(Attenuation!$K:$K,($H6-1+MIN(MAX(IFERROR(MATCH(LN(M$5),INDEX(Attenuation!$J:$J,$H6):INDEX(Attenuation!$J:$J,$H6+$I6-1),1),1),1),$I6-1))):INDEX(Attenuation!$K:$K,($H6-1+MIN(MAX(IFERROR(MATCH(LN(M$5),INDEX(Attenuation!$J:$J,$H6):INDEX(Attenuation!$J:$J,$H6+$I6-1),1),1),1),$I6-1))+1),INDEX(Attenuation!$J:$J,($H6-1+MIN(MAX(IFERROR(MATCH(LN(M$5),INDEX(Attenuation!$J:$J,$H6):INDEX(Attenuation!$J:$J,$H6+$I6-1),1),1),1),$I6-1))):INDEX(Attenuation!$J:$J,($H6-1+MIN(MAX(IFERROR(MATCH(LN(M$5),INDEX(Attenuation!$J:$J,$H6):INDEX(Attenuation!$J:$J,$H6+$I6-1),1),1),1),$I6-1))+1))))) -> 20.95305 | N6: =IF($A6="","",IF(N$5>2*$G6,"",EXP(FORECAST(LN(N$5),INDEX(Attenuation!$K:$K,($H6-1+MIN(MAX(IFERROR(MATCH(LN(N$5),INDEX(Attenuation!$J:$J,$H6):INDEX(Attenuation!$J:$J,$H6+$I6-1),1),1),1),$I6-1))):INDEX(Attenuation!$K:$K,($H6-1+MIN(MAX(IFERROR(MATCH(LN(N$5),INDEX(Attenuation!$J:$J,$H6):INDEX(Attenuation!$J:$J,$H6+$I6-1),1),1),1),$I6-1))+1),INDEX(Attenuation!$J:$J,($H6-1+MIN(MAX(IFERROR(MATCH(LN(N$5),INDEX(Attenuation!$J:$J,$H6):INDEX(Attenuation!$J:$J,$H6+$I6-1),1),1),1),$I6-1))):INDEX(Attenuation!$J:$J,($H6-1+MIN(MAX(IFERROR(MATCH(LN(N$5),INDEX(Attenuation!$J:$J,$H6):INDEX(Attenuation!$J:$J,$H6+$I6-1),1),1),1),$I6-1))+1))))) -> 24.548466 | O6: =IF($A6="","",IF(O$5>2*$G6,"",EXP(FORECAST(LN(O$5),INDEX(Attenuation!$K:$K,($H6-1+MIN(MAX(IFERROR(MATCH(LN(O$5),INDEX(Attenuation!$J:$J,$H6):INDEX(Attenuation!$J:$J,$H6+$I6-1),1),1),1),$I6-1))):INDEX(Attenuation!$K:$K,($H6-1+MIN(MAX(IFERROR(MATCH(LN(O$5),INDEX(Attenuation!$J:$J,$H6):INDEX(Attenuation!$J:$J,$H6+$I6-1),1),1),1),$I6-1))+1),INDEX(Attenuation!$J:$J,($H6-1+MIN(MAX(IFERROR(MATCH(LN(O$5),INDEX(Attenuation!$J:$J,$H6):INDEX(Attenuation!$J:$J,$H6+$I6-1),1),1),1),$I6-1))):INDEX(Attenuation!$J:$J,($H6-1+MIN(MAX(IFERROR(MATCH(LN(O$5),INDEX(Attenuation!$J:$J,$H6):INDEX(Attenuation!$J:$J,$H6+$I6-1),1),1),1),$I6-1))+1))))) -> 27.467712 | P6: =IF($A6="","",IF(P$5>2*$G6,"",EXP(FORECAST(LN(P$5),INDEX(Attenuation!$K:$K,($H6-1+MIN(MAX(IFERROR(MATCH(LN(P$5),INDEX(Attenuation!$J:$J,$H6):INDEX(Attenuation!$J:$J,$H6+$I6-1),1),1),1),$I6-1))):INDEX(Attenuation!$K:$K,($H6-1+MIN(MAX(IFERROR(MATCH(LN(P$5),INDEX(Attenuation!$J:$J,$H6):INDEX(Attenuation!$J:$J,$H6+$I6-1),1),1),1),$I6-1))+1),INDEX(Attenuation!$J:$J,($H6-1+MIN(MAX(IFERROR(MATCH(LN(P$5),INDEX(Attenuation!$J:$J,$H6):INDEX(Attenuation!$J:$J,$H6+$I6-1),1),1),1),$I6-1))):INDEX(Attenuation!$J:$J,($H6-1+MIN(MAX(IFERROR(MATCH(LN(P$5),INDEX(Attenuation!$J:$J,$H6):INDEX(Attenuation!$J:$J,$H6+$I6-1),1),1),1),$I6-1))+1))))) -> 34.448819 | Q6: =IF($A6="","",IF(Q$5>2*$G6,"",EXP(FORECAST(LN(Q$5),INDEX(Attenuation!$K:$K,($H6-1+MIN(MAX(IFERROR(MATCH(LN(Q$5),INDEX(Attenuation!$J:$J,$H6):INDEX(Attenuation!$J:$J,$H6+$I6-1),1),1),1),$I6-1))):INDEX(Attenuation!$K:$K,($H6-1+MIN(MAX(IFERROR(MATCH(LN(Q$5),INDEX(Attenuation!$J:$J,$H6):INDEX(Attenuation!$J:$J,$H6+$I6-1),1),1),1),$I6-1))+1),INDEX(Attenuation!$J:$J,($H6-1+MIN(MAX(IFERROR(MATCH(LN(Q$5),INDEX(Attenuation!$J:$J,$H6):INDEX(Attenuation!$J:$J,$H6+$I6-1),1),1),1),$I6-1))):INDEX(Attenuation!$J:$J,($H6-1+MIN(MAX(IFERROR(MATCH(LN(Q$5),INDEX(Attenuation!$J:$J,$H6):INDEX(Attenuation!$J:$J,$H6+$I6-1),1),1),1),$I6-1))+1))))) -> 53.93656 | ... U6: =IF($A6="","",IF(U$5>2*$G6,"",EXP(FORECAST(LN(U$5),INDEX(Attenuation!$K:$K,($H6-1+MIN(MAX(IFERROR(MATCH(LN(U$5),INDEX(Attenuation!$J:$J,$H6):INDEX(Attenuation!$J:$J,$H6+$I6-1),1),1),1),$I6-1))):INDEX(Attenuation!$K:$K,($H6-1+MIN(MAX(IFERROR(MATCH(LN(U$5),INDEX(Attenuation!$J:$J,$H6):INDEX(Attenuation!$J:$J,$H6+$I6-1),1),1),1),$I6-1))+1),INDEX(Attenuation!$J:$J,($H6-1+MIN(MAX(IFERROR(MATCH(LN(U$5),INDEX(Attenuation!$J:$J,$H6):INDEX(Attenuation!$J:$J,$H6+$I6-1),1),1),1),$I6-1))):INDEX(Attenuation!$J:$J,($H6-1+MIN(MAX(IFERROR(MATCH(LN(U$5),INDEX(Attenuation!$J:$J,$H6):INDEX(Attenuation!$J:$J,$H6+$I6-1),1),1),1),$I6-1))+1))))) | W6: =IF(J6="","",J6*0.3048) -> 3.1625245 | X6: =IF(K6="","",K6*0.3048) -> 3.9469789 | Y6: =IF(L6="","",L6*0.3048) -> 4.9724728 | Z6: =IF(M6="","",M6*0.3048) -> 6.3864896 | AA6: =IF(N6="","",N6*0.3048) -> 7.4823724 | AB6: =IF(O6="","",O6*0.3048) -> 8.3721588 | AC6: =IF(P6="","",P6*0.3048) -> 10.5 | AD6: =IF(Q6="","",Q6*0.3048) -> 16.439864 | ... AH6: =IF(U6="","",U6*0.3048)
A7: =IF(ROWS($A$6:A7)>COUNTA(Cables!$A:$A)-1,"",INDEX(Cables!$A:$A,ROWS($A$6:A7)+1)) -> BEL-8216 | B7: =IF($A7="","",IF(INDEX(Cables!$B:$B,MATCH($A7,Cables!$A:$A,0))="","",INDEX(Cables!$B:$B,MATCH($A7,Cables!$A:$A,0)))) -> Belden 8216 (RG-174) | C7: =IF($A7="","",IF(INDEX(Cables!$F:$F,MATCH($A7,Cables!$A:$A,0))="","",INDEX(Cables!$F:$F,MATCH($A7,Cables!$A:$A,0)))) -> 50 | D7: =IF($A7="","",IF(INDEX(Cables!$H:$H,MATCH($A7,Cables!$A:$A,0))="","",INDEX(Cables!$H:$H,MATCH($A7,Cables!$A:$A,0)))) -> 2.79 | E7: =IF($A7="","",IF(INDEX(Cables!$Q:$Q,MATCH($A7,Cables!$A:$A,0))="","",INDEX(Cables!$Q:$Q,MATCH($A7,Cables!$A:$A,0)))) -> 0.66 | F7: =IF($A7="","",IF(INDEX(Cables!$AQ:$AQ,MATCH($A7,Cables!$A:$A,0))="","",INDEX(Cables!$AQ:$AQ,MATCH($A7,Cables!$A:$A,0)))) -> 1 | G7: =IF($A7="","",IF(INDEX(Cables!$AR:$AR,MATCH($A7,Cables!$A:$A,0))="","",INDEX(Cables!$AR:$AR,MATCH($A7,Cables!$A:$A,0)))) -> 1000 | H7: =IF($A7="","",IF(INDEX(Cables!$AO:$AO,MATCH($A7,Cables!$A:$A,0))="","",INDEX(Cables!$AO:$AO,MATCH($A7,Cables!$A:$A,0)))) -> 11 | I7: =IF($A7="","",IF(INDEX(Cables!$AP:$AP,MATCH($A7,Cables!$A:$A,0))="","",INDEX(Cables!$AP:$AP,MATCH($A7,Cables!$A:$A,0)))) -> 9 | J7: =IF($A7="","",IF(J$5>2*$G7,"",EXP(FORECAST(LN(J$5),INDEX(Attenuation!$K:$K,($H7-1+MIN(MAX(IFERROR(MATCH(LN(J$5),INDEX(Attenuation!$J:$J,$H7):INDEX(Attenuation!$J:$J,$H7+$I7-1),1),1),1),$I7-1))):INDEX(Attenuation!$K:$K,($H7-1+MIN(MAX(IFERROR(MATCH(LN(J$5),INDEX(Attenuation!$J:$J,$H7):INDEX(Attenuation!$J:$J,$H7+$I7-1),1),1),1),$I7-1))+1),INDEX(Attenuation!$J:$J,($H7-1+MIN(MAX(IFERROR(MATCH(LN(J$5),INDEX(Attenuation!$J:$J,$H7):INDEX(Attenuation!$J:$J,$H7+$I7-1),1),1),1),$I7-1))):INDEX(Attenuation!$J:$J,($H7-1+MIN(MAX(IFERROR(MATCH(LN(J$5),INDEX(Attenuation!$J:$J,$H7):INDEX(Attenuation!$J:$J,$H7+$I7-1),1),1),1),$I7-1))+1))))) -> 7.1769986 | K7: =IF($A7="","",IF(K$5>2*$G7,"",EXP(FORECAST(LN(K$5),INDEX(Attenuation!$K:$K,($H7-1+MIN(MAX(IFERROR(MATCH(LN(K$5),INDEX(Attenuation!$J:$J,$H7):INDEX(Attenuation!$J:$J,$H7+$I7-1),1),1),1),$I7-1))):INDEX(Attenuation!$K:$K,($H7-1+MIN(MAX(IFERROR(MATCH(LN(K$5),INDEX(Attenuation!$J:$J,$H7):INDEX(Attenuation!$J:$J,$H7+$I7-1),1),1),1),$I7-1))+1),INDEX(Attenuation!$J:$J,($H7-1+MIN(MAX(IFERROR(MATCH(LN(K$5),INDEX(Attenuation!$J:$J,$H7):INDEX(Attenuation!$J:$J,$H7+$I7-1),1),1),1),$I7-1))):INDEX(Attenuation!$J:$J,($H7-1+MIN(MAX(IFERROR(MATCH(LN(K$5),INDEX(Attenuation!$J:$J,$H7):INDEX(Attenuation!$J:$J,$H7+$I7-1),1),1),1),$I7-1))+1))))) -> 8.4175281 | L7: =IF($A7="","",IF(L$5>2*$G7,"",EXP(FORECAST(LN(L$5),INDEX(Attenuation!$K:$K,($H7-1+MIN(MAX(IFERROR(MATCH(LN(L$5),INDEX(Attenuation!$J:$J,$H7):INDEX(Attenuation!$J:$J,$H7+$I7-1),1),1),1),$I7-1))):INDEX(Attenuation!$K:$K,($H7-1+MIN(MAX(IFERROR(MATCH(LN(L$5),INDEX(Attenuation!$J:$J,$H7):INDEX(Attenuation!$J:$J,$H7+$I7-1),1),1),1),$I7-1))+1),INDEX(Attenuation!$J:$J,($H7-1+MIN(MAX(IFERROR(MATCH(LN(L$5),INDEX(Attenuation!$J:$J,$H7):INDEX(Attenuation!$J:$J,$H7+$I7-1),1),1),1),$I7-1))):INDEX(Attenuation!$J:$J,($H7-1+MIN(MAX(IFERROR(MATCH(LN(L$5),INDEX(Attenuation!$J:$J,$H7):INDEX(Attenuation!$J:$J,$H7+$I7-1),1),1),1),$I7-1))+1))))) -> 9.9393877 | M7: =IF($A7="","",IF(M$5>2*$G7,"",EXP(FORECAST(LN(M$5),INDEX(Attenuation!$K:$K,($H7-1+MIN(MAX(IFERROR(MATCH(LN(M$5),INDEX(Attenuation!$J:$J,$H7):INDEX(Attenuation!$J:$J,$H7+$I7-1),1),1),1),$I7-1))):INDEX(Attenuation!$K:$K,($H7-1+MIN(MAX(IFERROR(MATCH(LN(M$5),INDEX(Attenuation!$J:$J,$H7):INDEX(Attenuation!$J:$J,$H7+$I7-1),1),1),1),$I7-1))+1),INDEX(Attenuation!$J:$J,($H7-1+MIN(MAX(IFERROR(MATCH(LN(M$5),INDEX(Attenuation!$J:$J,$H7):INDEX(Attenuation!$J:$J,$H7+$I7-1),1),1),1),$I7-1))):INDEX(Attenuation!$J:$J,($H7-1+MIN(MAX(IFERROR(MATCH(LN(M$5),INDEX(Attenuation!$J:$J,$H7):INDEX(Attenuation!$J:$J,$H7+$I7-1),1),1),1),$I7-1))+1))))) -> 12.181512 | N7: =IF($A7="","",IF(N$5>2*$G7,"",EXP(FORECAST(LN(N$5),INDEX(Attenuation!$K:$K,($H7-1+MIN(MAX(IFERROR(MATCH(LN(N$5),INDEX(Attenuation!$J:$J,$H7):INDEX(Attenuation!$J:$J,$H7+$I7-1),1),1),1),$I7-1))):INDEX(Attenuation!$K:$K,($H7-1+MIN(MAX(IFERROR(MATCH(LN(N$5),INDEX(Attenuation!$J:$J,$H7):INDEX(Attenuation!$J:$J,$H7+$I7-1),1),1),1),$I7-1))+1),INDEX(Attenuation!$J:$J,($H7-1+MIN(MAX(IFERROR(MATCH(LN(N$5),INDEX(Attenuation!$J:$J,$H7):INDEX(Attenuation!$J:$J,$H7+$I7-1),1),1),1),$I7-1))):INDEX(Attenuation!$J:$J,($H7-1+MIN(MAX(IFERROR(MATCH(LN(N$5),INDEX(Attenuation!$J:$J,$H7):INDEX(Attenuation!$J:$J,$H7+$I7-1),1),1),1),$I7-1))+1))))) -> 14.041138 | O7: =IF($A7="","",IF(O$5>2*$G7,"",EXP(FORECAST(LN(O$5),INDEX(Attenuation!$K:$K,($H7-1+MIN(MAX(IFERROR(MATCH(LN(O$5),INDEX(Attenuation!$J:$J,$H7):INDEX(Attenuation!$J:$J,$H7+$I7-1),1),1),1),$I7-1))):INDEX(Attenuation!$K:$K,($H7-1+MIN(MAX(IFERROR(MATCH(LN(O$5),INDEX(Attenuation!$J:$J,$H7):INDEX(Attenuation!$J:$J,$H7+$I7-1),1),1),1),$I7-1))+1),INDEX(Attenuation!$J:$J,($H7-1+MIN(MAX(IFERROR(MATCH(LN(O$5),INDEX(Attenuation!$J:$J,$H7):INDEX(Attenuation!$J:$J,$H7+$I7-1),1),1),1),$I7-1))):INDEX(Attenuation!$J:$J,($H7-1+MIN(MAX(IFERROR(MATCH(LN(O$5),INDEX(Attenuation!$J:$J,$H7):INDEX(Attenuation!$J:$J,$H7+$I7-1),1),1),1),$I7-1))+1))))) -> 15.530303 | P7: =IF($A7="","",IF(P$5>2*$G7,"",EXP(FORECAST(LN(P$5),INDEX(Attenuation!$K:$K,($H7-1+MIN(MAX(IFERROR(MATCH(LN(P$5),INDEX(Attenuation!$J:$J,$H7):INDEX(Attenuation!$J:$J,$H7+$I7-1),1),1),1),$I7-1))):INDEX(Attenuation!$K:$K,($H7-1+MIN(MAX(IFERROR(MATCH(LN(P$5),INDEX(Attenuation!$J:$J,$H7):INDEX(Attenuation!$J:$J,$H7+$I7-1),1),1),1),$I7-1))+1),INDEX(Attenuation!$J:$J,($H7-1+MIN(MAX(IFERROR(MATCH(LN(P$5),INDEX(Attenuation!$J:$J,$H7):INDEX(Attenuation!$J:$J,$H7+$I7-1),1),1),1),$I7-1))):INDEX(Attenuation!$J:$J,($H7-1+MIN(MAX(IFERROR(MATCH(LN(P$5),INDEX(Attenuation!$J:$J,$H7):INDEX(Attenuation!$J:$J,$H7+$I7-1),1),1),1),$I7-1))+1))))) -> 19.028871 | Q7: =IF($A7="","",IF(Q$5>2*$G7,"",EXP(FORECAST(LN(Q$5),INDEX(Attenuation!$K:$K,($H7-1+MIN(MAX(IFERROR(MATCH(LN(Q$5),INDEX(Attenuation!$J:$J,$H7):INDEX(Attenuation!$J:$J,$H7+$I7-1),1),1),1),$I7-1))):INDEX(Attenuation!$K:$K,($H7-1+MIN(MAX(IFERROR(MATCH(LN(Q$5),INDEX(Attenuation!$J:$J,$H7):INDEX(Attenuation!$J:$J,$H7+$I7-1),1),1),1),$I7-1))+1),INDEX(Attenuation!$J:$J,($H7-1+MIN(MAX(IFERROR(MATCH(LN(Q$5),INDEX(Attenuation!$J:$J,$H7):INDEX(Attenuation!$J:$J,$H7+$I7-1),1),1),1),$I7-1))):INDEX(Attenuation!$J:$J,($H7-1+MIN(MAX(IFERROR(MATCH(LN(Q$5),INDEX(Attenuation!$J:$J,$H7):INDEX(Attenuation!$J:$J,$H7+$I7-1),1),1),1),$I7-1))+1))))) -> 33.968781 | ... U7: =IF($A7="","",IF(U$5>2*$G7,"",EXP(FORECAST(LN(U$5),INDEX(Attenuation!$K:$K,($H7-1+MIN(MAX(IFERROR(MATCH(LN(U$5),INDEX(Attenuation!$J:$J,$H7):INDEX(Attenuation!$J:$J,$H7+$I7-1),1),1),1),$I7-1))):INDEX(Attenuation!$K:$K,($H7-1+MIN(MAX(IFERROR(MATCH(LN(U$5),INDEX(Attenuation!$J:$J,$H7):INDEX(Attenuation!$J:$J,$H7+$I7-1),1),1),1),$I7-1))+1),INDEX(Attenuation!$J:$J,($H7-1+MIN(MAX(IFERROR(MATCH(LN(U$5),INDEX(Attenuation!$J:$J,$H7):INDEX(Attenuation!$J:$J,$H7+$I7-1),1),1),1),$I7-1))):INDEX(Attenuation!$J:$J,($H7-1+MIN(MAX(IFERROR(MATCH(LN(U$5),INDEX(Attenuation!$J:$J,$H7):INDEX(Attenuation!$J:$J,$H7+$I7-1),1),1),1),$I7-1))+1))))) | W7: =IF(J7="","",J7*0.3048) -> 2.1875492 | X7: =IF(K7="","",K7*0.3048) -> 2.5656626 | Y7: =IF(L7="","",L7*0.3048) -> 3.0295254 | Z7: =IF(M7="","",M7*0.3048) -> 3.7129248 | AA7: =IF(N7="","",N7*0.3048) -> 4.2797388 | AB7: =IF(O7="","",O7*0.3048) -> 4.7336364 | AC7: =IF(P7="","",P7*0.3048) -> 5.8 | AD7: =IF(Q7="","",Q7*0.3048) -> 10.353685 | ... AH7: =IF(U7="","",U7*0.3048)
A8: =IF(ROWS($A$6:A8)>COUNTA(Cables!$A:$A)-1,"",INDEX(Cables!$A:$A,ROWS($A$6:A8)+1)) -> BEL-84316 | B8: =IF($A8="","",IF(INDEX(Cables!$B:$B,MATCH($A8,Cables!$A:$A,0))="","",INDEX(Cables!$B:$B,MATCH($A8,Cables!$A:$A,0)))) -> Belden 84316 (RG-316) | C8: =IF($A8="","",IF(INDEX(Cables!$F:$F,MATCH($A8,Cables!$A:$A,0))="","",INDEX(Cables!$F:$F,MATCH($A8,Cables!$A:$A,0)))) -> 50 | D8: =IF($A8="","",IF(INDEX(Cables!$H:$H,MATCH($A8,Cables!$A:$A,0))="","",INDEX(Cables!$H:$H,MATCH($A8,Cables!$A:$A,0)))) -> 2.5 | E8: =IF($A8="","",IF(INDEX(Cables!$Q:$Q,MATCH($A8,Cables!$A:$A,0))="","",INDEX(Cables!$Q:$Q,MATCH($A8,Cables!$A:$A,0)))) -> 0.7 | F8: =IF($A8="","",IF(INDEX(Cables!$AQ:$AQ,MATCH($A8,Cables!$A:$A,0))="","",INDEX(Cables!$AQ:$AQ,MATCH($A8,Cables!$A:$A,0)))) -> 1 | G8: =IF($A8="","",IF(INDEX(Cables!$AR:$AR,MATCH($A8,Cables!$A:$A,0))="","",INDEX(Cables!$AR:$AR,MATCH($A8,Cables!$A:$A,0)))) -> 3000 | H8: =IF($A8="","",IF(INDEX(Cables!$AO:$AO,MATCH($A8,Cables!$A:$A,0))="","",INDEX(Cables!$AO:$AO,MATCH($A8,Cables!$A:$A,0)))) -> 20 | I8: =IF($A8="","",IF(INDEX(Cables!$AP:$AP,MATCH($A8,Cables!$A:$A,0))="","",INDEX(Cables!$AP:$AP,MATCH($A8,Cables!$A:$A,0)))) -> 13 | J8: =IF($A8="","",IF(J$5>2*$G8,"",EXP(FORECAST(LN(J$5),INDEX(Attenuation!$K:$K,($H8-1+MIN(MAX(IFERROR(MATCH(LN(J$5),INDEX(Attenuation!$J:$J,$H8):INDEX(Attenuation!$J:$J,$H8+$I8-1),1),1),1),$I8-1))):INDEX(Attenuation!$K:$K,($H8-1+MIN(MAX(IFERROR(MATCH(LN(J$5),INDEX(Attenuation!$J:$J,$H8):INDEX(Attenuation!$J:$J,$H8+$I8-1),1),1),1),$I8-1))+1),INDEX(Attenuation!$J:$J,($H8-1+MIN(MAX(IFERROR(MATCH(LN(J$5),INDEX(Attenuation!$J:$J,$H8):INDEX(Attenuation!$J:$J,$H8+$I8-1),1),1),1),$I8-1))):INDEX(Attenuation!$J:$J,($H8-1+MIN(MAX(IFERROR(MATCH(LN(J$5),INDEX(Attenuation!$J:$J,$H8):INDEX(Attenuation!$J:$J,$H8+$I8-1),1),1),1),$I8-1))+1))))) -> 4.8424907 | K8: =IF($A8="","",IF(K$5>2*$G8,"",EXP(FORECAST(LN(K$5),INDEX(Attenuation!$K:$K,($H8-1+MIN(MAX(IFERROR(MATCH(LN(K$5),INDEX(Attenuation!$J:$J,$H8):INDEX(Attenuation!$J:$J,$H8+$I8-1),1),1),1),$I8-1))):INDEX(Attenuation!$K:$K,($H8-1+MIN(MAX(IFERROR(MATCH(LN(K$5),INDEX(Attenuation!$J:$J,$H8):INDEX(Attenuation!$J:$J,$H8+$I8-1),1),1),1),$I8-1))+1),INDEX(Attenuation!$J:$J,($H8-1+MIN(MAX(IFERROR(MATCH(LN(K$5),INDEX(Attenuation!$J:$J,$H8):INDEX(Attenuation!$J:$J,$H8+$I8-1),1),1),1),$I8-1))):INDEX(Attenuation!$J:$J,($H8-1+MIN(MAX(IFERROR(MATCH(LN(K$5),INDEX(Attenuation!$J:$J,$H8):INDEX(Attenuation!$J:$J,$H8+$I8-1),1),1),1),$I8-1))+1))))) -> 6.120368 | L8: =IF($A8="","",IF(L$5>2*$G8,"",EXP(FORECAST(LN(L$5),INDEX(Attenuation!$K:$K,($H8-1+MIN(MAX(IFERROR(MATCH(LN(L$5),INDEX(Attenuation!$J:$J,$H8):INDEX(Attenuation!$J:$J,$H8+$I8-1),1),1),1),$I8-1))):INDEX(Attenuation!$K:$K,($H8-1+MIN(MAX(IFERROR(MATCH(LN(L$5),INDEX(Attenuation!$J:$J,$H8):INDEX(Attenuation!$J:$J,$H8+$I8-1),1),1),1),$I8-1))+1),INDEX(Attenuation!$J:$J,($H8-1+MIN(MAX(IFERROR(MATCH(LN(L$5),INDEX(Attenuation!$J:$J,$H8):INDEX(Attenuation!$J:$J,$H8+$I8-1),1),1),1),$I8-1))):INDEX(Attenuation!$J:$J,($H8-1+MIN(MAX(IFERROR(MATCH(LN(L$5),INDEX(Attenuation!$J:$J,$H8):INDEX(Attenuation!$J:$J,$H8+$I8-1),1),1),1),$I8-1))+1))))) -> 7.8125901 | M8: =IF($A8="","",IF(M$5>2*$G8,"",EXP(FORECAST(LN(M$5),INDEX(Attenuation!$K:$K,($H8-1+MIN(MAX(IFERROR(MATCH(LN(M$5),INDEX(Attenuation!$J:$J,$H8):INDEX(Attenuation!$J:$J,$H8+$I8-1),1),1),1),$I8-1))):INDEX(Attenuation!$K:$K,($H8-1+MIN(MAX(IFERROR(MATCH(LN(M$5),INDEX(Attenuation!$J:$J,$H8):INDEX(Attenuation!$J:$J,$H8+$I8-1),1),1),1),$I8-1))+1),INDEX(Attenuation!$J:$J,($H8-1+MIN(MAX(IFERROR(MATCH(LN(M$5),INDEX(Attenuation!$J:$J,$H8):INDEX(Attenuation!$J:$J,$H8+$I8-1),1),1),1),$I8-1))):INDEX(Attenuation!$J:$J,($H8-1+MIN(MAX(IFERROR(MATCH(LN(M$5),INDEX(Attenuation!$J:$J,$H8):INDEX(Attenuation!$J:$J,$H8+$I8-1),1),1),1),$I8-1))+1))))) -> 10.317743 | N8: =IF($A8="","",IF(N$5>2*$G8,"",EXP(FORECAST(LN(N$5),INDEX(Attenuation!$K:$K,($H8-1+MIN(MAX(IFERROR(MATCH(LN(N$5),INDEX(Attenuation!$J:$J,$H8):INDEX(Attenuation!$J:$J,$H8+$I8-1),1),1),1),$I8-1))):INDEX(Attenuation!$K:$K,($H8-1+MIN(MAX(IFERROR(MATCH(LN(N$5),INDEX(Attenuation!$J:$J,$H8):INDEX(Attenuation!$J:$J,$H8+$I8-1),1),1),1),$I8-1))+1),INDEX(Attenuation!$J:$J,($H8-1+MIN(MAX(IFERROR(MATCH(LN(N$5),INDEX(Attenuation!$J:$J,$H8):INDEX(Attenuation!$J:$J,$H8+$I8-1),1),1),1),$I8-1))):INDEX(Attenuation!$J:$J,($H8-1+MIN(MAX(IFERROR(MATCH(LN(N$5),INDEX(Attenuation!$J:$J,$H8):INDEX(Attenuation!$J:$J,$H8+$I8-1),1),1),1),$I8-1))+1))))) -> 12.399441 | O8: =IF($A8="","",IF(O$5>2*$G8,"",EXP(FORECAST(LN(O$5),INDEX(Attenuation!$K:$K,($H8-1+MIN(MAX(IFERROR(MATCH(LN(O$5),INDEX(Attenuation!$J:$J,$H8):INDEX(Attenuation!$J:$J,$H8+$I8-1),1),1),1),$I8-1))):INDEX(Attenuation!$K:$K,($H8-1+MIN(MAX(IFERROR(MATCH(LN(O$5),INDEX(Attenuation!$J:$J,$H8):INDEX(Attenuation!$J:$J,$H8+$I8-1),1),1),1),$I8-1))+1),INDEX(Attenuation!$J:$J,($H8-1+MIN(MAX(IFERROR(MATCH(LN(O$5),INDEX(Attenuation!$J:$J,$H8):INDEX(Attenuation!$J:$J,$H8+$I8-1),1),1),1),$I8-1))):INDEX(Attenuation!$J:$J,($H8-1+MIN(MAX(IFERROR(MATCH(LN(O$5),INDEX(Attenuation!$J:$J,$H8):INDEX(Attenuation!$J:$J,$H8+$I8-1),1),1),1),$I8-1))+1))))) -> 14.126465 | P8: =IF($A8="","",IF(P$5>2*$G8,"",EXP(FORECAST(LN(P$5),INDEX(Attenuation!$K:$K,($H8-1+MIN(MAX(IFERROR(MATCH(LN(P$5),INDEX(Attenuation!$J:$J,$H8):INDEX(Attenuation!$J:$J,$H8+$I8-1),1),1),1),$I8-1))):INDEX(Attenuation!$K:$K,($H8-1+MIN(MAX(IFERROR(MATCH(LN(P$5),INDEX(Attenuation!$J:$J,$H8):INDEX(Attenuation!$J:$J,$H8+$I8-1),1),1),1),$I8-1))+1),INDEX(Attenuation!$J:$J,($H8-1+MIN(MAX(IFERROR(MATCH(LN(P$5),INDEX(Attenuation!$J:$J,$H8):INDEX(Attenuation!$J:$J,$H8+$I8-1),1),1),1),$I8-1))):INDEX(Attenuation!$J:$J,($H8-1+MIN(MAX(IFERROR(MATCH(LN(P$5),INDEX(Attenuation!$J:$J,$H8):INDEX(Attenuation!$J:$J,$H8+$I8-1),1),1),1),$I8-1))+1))))) -> 18.372703 | Q8: =IF($A8="","",IF(Q$5>2*$G8,"",EXP(FORECAST(LN(Q$5),INDEX(Attenuation!$K:$K,($H8-1+MIN(MAX(IFERROR(MATCH(LN(Q$5),INDEX(Attenuation!$J:$J,$H8):INDEX(Attenuation!$J:$J,$H8+$I8-1),1),1),1),$I8-1))):INDEX(Attenuation!$K:$K,($H8-1+MIN(MAX(IFERROR(MATCH(LN(Q$5),INDEX(Attenuation!$J:$J,$H8):INDEX(Attenuation!$J:$J,$H8+$I8-1),1),1),1),$I8-1))+1),INDEX(Attenuation!$J:$J,($H8-1+MIN(MAX(IFERROR(MATCH(LN(Q$5),INDEX(Attenuation!$J:$J,$H8):INDEX(Attenuation!$J:$J,$H8+$I8-1),1),1),1),$I8-1))):INDEX(Attenuation!$J:$J,($H8-1+MIN(MAX(IFERROR(MATCH(LN(Q$5),INDEX(Attenuation!$J:$J,$H8):INDEX(Attenuation!$J:$J,$H8+$I8-1),1),1),1),$I8-1))+1))))) -> 33.058901 | ... U8: =IF($A8="","",IF(U$5>2*$G8,"",EXP(FORECAST(LN(U$5),INDEX(Attenuation!$K:$K,($H8-1+MIN(MAX(IFERROR(MATCH(LN(U$5),INDEX(Attenuation!$J:$J,$H8):INDEX(Attenuation!$J:$J,$H8+$I8-1),1),1),1),$I8-1))):INDEX(Attenuation!$K:$K,($H8-1+MIN(MAX(IFERROR(MATCH(LN(U$5),INDEX(Attenuation!$J:$J,$H8):INDEX(Attenuation!$J:$J,$H8+$I8-1),1),1),1),$I8-1))+1),INDEX(Attenuation!$J:$J,($H8-1+MIN(MAX(IFERROR(MATCH(LN(U$5),INDEX(Attenuation!$J:$J,$H8):INDEX(Attenuation!$J:$J,$H8+$I8-1),1),1),1),$I8-1))):INDEX(Attenuation!$J:$J,($H8-1+MIN(MAX(IFERROR(MATCH(LN(U$5),INDEX(Attenuation!$J:$J,$H8):INDEX(Attenuation!$J:$J,$H8+$I8-1),1),1),1),$I8-1))+1))))) -> 255.02632 | W8: =IF(J8="","",J8*0.3048) -> 1.4759912 | X8: =IF(K8="","",K8*0.3048) -> 1.8654882 | Y8: =IF(L8="","",L8*0.3048) -> 2.3812775 | Z8: =IF(M8="","",M8*0.3048) -> 3.144848 | AA8: =IF(N8="","",N8*0.3048) -> 3.7793498 | AB8: =IF(O8="","",O8*0.3048) -> 4.3057464 | AC8: =IF(P8="","",P8*0.3048) -> 5.6 | AD8: =IF(Q8="","",Q8*0.3048) -> 10.076353 | ... AH8: =IF(U8="","",U8*0.3048) -> 77.732021
A9: =IF(ROWS($A$6:A9)>COUNTA(Cables!$A:$A)-1,"",INDEX(Cables!$A:$A,ROWS($A$6:A9)+1)) -> BEL-83269 | B9: =IF($A9="","",IF(INDEX(Cables!$B:$B,MATCH($A9,Cables!$A:$A,0))="","",INDEX(Cables!$B:$B,MATCH($A9,Cables!$A:$A,0)))) -> Belden 83269 (RG-188) | C9: =IF($A9="","",IF(INDEX(Cables!$F:$F,MATCH($A9,Cables!$A:$A,0))="","",INDEX(Cables!$F:$F,MATCH($A9,Cables!$A:$A,0)))) -> 50 | D9: =IF($A9="","",IF(INDEX(Cables!$H:$H,MATCH($A9,Cables!$A:$A,0))="","",INDEX(Cables!$H:$H,MATCH($A9,Cables!$A:$A,0)))) -> 2.54 | E9: =IF($A9="","",IF(INDEX(Cables!$Q:$Q,MATCH($A9,Cables!$A:$A,0))="","",INDEX(Cables!$Q:$Q,MATCH($A9,Cables!$A:$A,0)))) -> 0.7 | F9: =IF($A9="","",IF(INDEX(Cables!$AQ:$AQ,MATCH($A9,Cables!$A:$A,0))="","",INDEX(Cables!$AQ:$AQ,MATCH($A9,Cables!$A:$A,0)))) -> 1 | G9: =IF($A9="","",IF(INDEX(Cables!$AR:$AR,MATCH($A9,Cables!$A:$A,0))="","",INDEX(Cables!$AR:$AR,MATCH($A9,Cables!$A:$A,0)))) -> 1000 | H9: =IF($A9="","",IF(INDEX(Cables!$AO:$AO,MATCH($A9,Cables!$A:$A,0))="","",INDEX(Cables!$AO:$AO,MATCH($A9,Cables!$A:$A,0)))) -> 33 | I9: =IF($A9="","",IF(INDEX(Cables!$AP:$AP,MATCH($A9,Cables!$A:$A,0))="","",INDEX(Cables!$AP:$AP,MATCH($A9,Cables!$A:$A,0)))) -> 9 | J9: =IF($A9="","",IF(J$5>2*$G9,"",EXP(FORECAST(LN(J$5),INDEX(Attenuation!$K:$K,($H9-1+MIN(MAX(IFERROR(MATCH(LN(J$5),INDEX(Attenuation!$J:$J,$H9):INDEX(Attenuation!$J:$J,$H9+$I9-1),1),1),1),$I9-1))):INDEX(Attenuation!$K:$K,($H9-1+MIN(MAX(IFERROR(MATCH(LN(J$5),INDEX(Attenuation!$J:$J,$H9):INDEX(Attenuation!$J:$J,$H9+$I9-1),1),1),1),$I9-1))+1),INDEX(Attenuation!$J:$J,($H9-1+MIN(MAX(IFERROR(MATCH(LN(J$5),INDEX(Attenuation!$J:$J,$H9):INDEX(Attenuation!$J:$J,$H9+$I9-1),1),1),1),$I9-1))):INDEX(Attenuation!$J:$J,($H9-1+MIN(MAX(IFERROR(MATCH(LN(J$5),INDEX(Attenuation!$J:$J,$H9):INDEX(Attenuation!$J:$J,$H9+$I9-1),1),1),1),$I9-1))+1))))) -> 4.8424907 | K9: =IF($A9="","",IF(K$5>2*$G9,"",EXP(FORECAST(LN(K$5),INDEX(Attenuation!$K:$K,($H9-1+MIN(MAX(IFERROR(MATCH(LN(K$5),INDEX(Attenuation!$J:$J,$H9):INDEX(Attenuation!$J:$J,$H9+$I9-1),1),1),1),$I9-1))):INDEX(Attenuation!$K:$K,($H9-1+MIN(MAX(IFERROR(MATCH(LN(K$5),INDEX(Attenuation!$J:$J,$H9):INDEX(Attenuation!$J:$J,$H9+$I9-1),1),1),1),$I9-1))+1),INDEX(Attenuation!$J:$J,($H9-1+MIN(MAX(IFERROR(MATCH(LN(K$5),INDEX(Attenuation!$J:$J,$H9):INDEX(Attenuation!$J:$J,$H9+$I9-1),1),1),1),$I9-1))):INDEX(Attenuation!$J:$J,($H9-1+MIN(MAX(IFERROR(MATCH(LN(K$5),INDEX(Attenuation!$J:$J,$H9):INDEX(Attenuation!$J:$J,$H9+$I9-1),1),1),1),$I9-1))+1))))) -> 6.120368 | L9: =IF($A9="","",IF(L$5>2*$G9,"",EXP(FORECAST(LN(L$5),INDEX(Attenuation!$K:$K,($H9-1+MIN(MAX(IFERROR(MATCH(LN(L$5),INDEX(Attenuation!$J:$J,$H9):INDEX(Attenuation!$J:$J,$H9+$I9-1),1),1),1),$I9-1))):INDEX(Attenuation!$K:$K,($H9-1+MIN(MAX(IFERROR(MATCH(LN(L$5),INDEX(Attenuation!$J:$J,$H9):INDEX(Attenuation!$J:$J,$H9+$I9-1),1),1),1),$I9-1))+1),INDEX(Attenuation!$J:$J,($H9-1+MIN(MAX(IFERROR(MATCH(LN(L$5),INDEX(Attenuation!$J:$J,$H9):INDEX(Attenuation!$J:$J,$H9+$I9-1),1),1),1),$I9-1))):INDEX(Attenuation!$J:$J,($H9-1+MIN(MAX(IFERROR(MATCH(LN(L$5),INDEX(Attenuation!$J:$J,$H9):INDEX(Attenuation!$J:$J,$H9+$I9-1),1),1),1),$I9-1))+1))))) -> 7.8125901 | M9: =IF($A9="","",IF(M$5>2*$G9,"",EXP(FORECAST(LN(M$5),INDEX(Attenuation!$K:$K,($H9-1+MIN(MAX(IFERROR(MATCH(LN(M$5),INDEX(Attenuation!$J:$J,$H9):INDEX(Attenuation!$J:$J,$H9+$I9-1),1),1),1),$I9-1))):INDEX(Attenuation!$K:$K,($H9-1+MIN(MAX(IFERROR(MATCH(LN(M$5),INDEX(Attenuation!$J:$J,$H9):INDEX(Attenuation!$J:$J,$H9+$I9-1),1),1),1),$I9-1))+1),INDEX(Attenuation!$J:$J,($H9-1+MIN(MAX(IFERROR(MATCH(LN(M$5),INDEX(Attenuation!$J:$J,$H9):INDEX(Attenuation!$J:$J,$H9+$I9-1),1),1),1),$I9-1))):INDEX(Attenuation!$J:$J,($H9-1+MIN(MAX(IFERROR(MATCH(LN(M$5),INDEX(Attenuation!$J:$J,$H9):INDEX(Attenuation!$J:$J,$H9+$I9-1),1),1),1),$I9-1))+1))))) -> 10.317743 | N9: =IF($A9="","",IF(N$5>2*$G9,"",EXP(FORECAST(LN(N$5),INDEX(Attenuation!$K:$K,($H9-1+MIN(MAX(IFERROR(MATCH(LN(N$5),INDEX(Attenuation!$J:$J,$H9):INDEX(Attenuation!$J:$J,$H9+$I9-1),1),1),1),$I9-1))):INDEX(Attenuation!$K:$K,($H9-1+MIN(MAX(IFERROR(MATCH(LN(N$5),INDEX(Attenuation!$J:$J,$H9):INDEX(Attenuation!$J:$J,$H9+$I9-1),1),1),1),$I9-1))+1),INDEX(Attenuation!$J:$J,($H9-1+MIN(MAX(IFERROR(MATCH(LN(N$5),INDEX(Attenuation!$J:$J,$H9):INDEX(Attenuation!$J:$J,$H9+$I9-1),1),1),1),$I9-1))):INDEX(Attenuation!$J:$J,($H9-1+MIN(MAX(IFERROR(MATCH(LN(N$5),INDEX(Attenuation!$J:$J,$H9):INDEX(Attenuation!$J:$J,$H9+$I9-1),1),1),1),$I9-1))+1))))) -> 12.399441 | O9: =IF($A9="","",IF(O$5>2*$G9,"",EXP(FORECAST(LN(O$5),INDEX(Attenuation!$K:$K,($H9-1+MIN(MAX(IFERROR(MATCH(LN(O$5),INDEX(Attenuation!$J:$J,$H9):INDEX(Attenuation!$J:$J,$H9+$I9-1),1),1),1),$I9-1))):INDEX(Attenuation!$K:$K,($H9-1+MIN(MAX(IFERROR(MATCH(LN(O$5),INDEX(Attenuation!$J:$J,$H9):INDEX(Attenuation!$J:$J,$H9+$I9-1),1),1),1),$I9-1))+1),INDEX(Attenuation!$J:$J,($H9-1+MIN(MAX(IFERROR(MATCH(LN(O$5),INDEX(Attenuation!$J:$J,$H9):INDEX(Attenuation!$J:$J,$H9+$I9-1),1),1),1),$I9-1))):INDEX(Attenuation!$J:$J,($H9-1+MIN(MAX(IFERROR(MATCH(LN(O$5),INDEX(Attenuation!$J:$J,$H9):INDEX(Attenuation!$J:$J,$H9+$I9-1),1),1),1),$I9-1))+1))))) -> 14.126465 | P9: =IF($A9="","",IF(P$5>2*$G9,"",EXP(FORECAST(LN(P$5),INDEX(Attenuation!$K:$K,($H9-1+MIN(MAX(IFERROR(MATCH(LN(P$5),INDEX(Attenuation!$J:$J,$H9):INDEX(Attenuation!$J:$J,$H9+$I9-1),1),1),1),$I9-1))):INDEX(Attenuation!$K:$K,($H9-1+MIN(MAX(IFERROR(MATCH(LN(P$5),INDEX(Attenuation!$J:$J,$H9):INDEX(Attenuation!$J:$J,$H9+$I9-1),1),1),1),$I9-1))+1),INDEX(Attenuation!$J:$J,($H9-1+MIN(MAX(IFERROR(MATCH(LN(P$5),INDEX(Attenuation!$J:$J,$H9):INDEX(Attenuation!$J:$J,$H9+$I9-1),1),1),1),$I9-1))):INDEX(Attenuation!$J:$J,($H9-1+MIN(MAX(IFERROR(MATCH(LN(P$5),INDEX(Attenuation!$J:$J,$H9):INDEX(Attenuation!$J:$J,$H9+$I9-1),1),1),1),$I9-1))+1))))) -> 18.372703 | Q9: =IF($A9="","",IF(Q$5>2*$G9,"",EXP(FORECAST(LN(Q$5),INDEX(Attenuation!$K:$K,($H9-1+MIN(MAX(IFERROR(MATCH(LN(Q$5),INDEX(Attenuation!$J:$J,$H9):INDEX(Attenuation!$J:$J,$H9+$I9-1),1),1),1),$I9-1))):INDEX(Attenuation!$K:$K,($H9-1+MIN(MAX(IFERROR(MATCH(LN(Q$5),INDEX(Attenuation!$J:$J,$H9):INDEX(Attenuation!$J:$J,$H9+$I9-1),1),1),1),$I9-1))+1),INDEX(Attenuation!$J:$J,($H9-1+MIN(MAX(IFERROR(MATCH(LN(Q$5),INDEX(Attenuation!$J:$J,$H9):INDEX(Attenuation!$J:$J,$H9+$I9-1),1),1),1),$I9-1))):INDEX(Attenuation!$J:$J,($H9-1+MIN(MAX(IFERROR(MATCH(LN(Q$5),INDEX(Attenuation!$J:$J,$H9):INDEX(Attenuation!$J:$J,$H9+$I9-1),1),1),1),$I9-1))+1))))) -> 33.058901 | ... U9: =IF($A9="","",IF(U$5>2*$G9,"",EXP(FORECAST(LN(U$5),INDEX(Attenuation!$K:$K,($H9-1+MIN(MAX(IFERROR(MATCH(LN(U$5),INDEX(Attenuation!$J:$J,$H9):INDEX(Attenuation!$J:$J,$H9+$I9-1),1),1),1),$I9-1))):INDEX(Attenuation!$K:$K,($H9-1+MIN(MAX(IFERROR(MATCH(LN(U$5),INDEX(Attenuation!$J:$J,$H9):INDEX(Attenuation!$J:$J,$H9+$I9-1),1),1),1),$I9-1))+1),INDEX(Attenuation!$J:$J,($H9-1+MIN(MAX(IFERROR(MATCH(LN(U$5),INDEX(Attenuation!$J:$J,$H9):INDEX(Attenuation!$J:$J,$H9+$I9-1),1),1),1),$I9-1))):INDEX(Attenuation!$J:$J,($H9-1+MIN(MAX(IFERROR(MATCH(LN(U$5),INDEX(Attenuation!$J:$J,$H9):INDEX(Attenuation!$J:$J,$H9+$I9-1),1),1),1),$I9-1))+1))))) | W9: =IF(J9="","",J9*0.3048) -> 1.4759912 | X9: =IF(K9="","",K9*0.3048) -> 1.8654882 | Y9: =IF(L9="","",L9*0.3048) -> 2.3812775 | Z9: =IF(M9="","",M9*0.3048) -> 3.144848 | AA9: =IF(N9="","",N9*0.3048) -> 3.7793498 | AB9: =IF(O9="","",O9*0.3048) -> 4.3057464 | AC9: =IF(P9="","",P9*0.3048) -> 5.6 | AD9: =IF(Q9="","",Q9*0.3048) -> 10.076353 | ... AH9: =IF(U9="","",U9*0.3048)
A10: =IF(ROWS($A$6:A10)>COUNTA(Cables!$A:$A)-1,"",INDEX(Cables!$A:$A,ROWS($A$6:A10)+1)) -> TMS-LMR100A | B10: =IF($A10="","",IF(INDEX(Cables!$B:$B,MATCH($A10,Cables!$A:$A,0))="","",INDEX(Cables!$B:$B,MATCH($A10,Cables!$A:$A,0)))) -> Times Microwave LMR-100A (Amphenol) | C10: =IF($A10="","",IF(INDEX(Cables!$F:$F,MATCH($A10,Cables!$A:$A,0))="","",INDEX(Cables!$F:$F,MATCH($A10,Cables!$A:$A,0)))) -> 50 | D10: =IF($A10="","",IF(INDEX(Cables!$H:$H,MATCH($A10,Cables!$A:$A,0))="","",INDEX(Cables!$H:$H,MATCH($A10,Cables!$A:$A,0)))) -> 2.79 | E10: =IF($A10="","",IF(INDEX(Cables!$Q:$Q,MATCH($A10,Cables!$A:$A,0))="","",INDEX(Cables!$Q:$Q,MATCH($A10,Cables!$A:$A,0)))) -> 0.66 | F10: =IF($A10="","",IF(INDEX(Cables!$AQ:$AQ,MATCH($A10,Cables!$A:$A,0))="","",INDEX(Cables!$AQ:$AQ,MATCH($A10,Cables!$A:$A,0)))) -> 30 | G10: =IF($A10="","",IF(INDEX(Cables!$AR:$AR,MATCH($A10,Cables!$A:$A,0))="","",INDEX(Cables!$AR:$AR,MATCH($A10,Cables!$A:$A,0)))) -> 2500 | H10: =IF($A10="","",IF(INDEX(Cables!$AO:$AO,MATCH($A10,Cables!$A:$A,0))="","",INDEX(Cables!$AO:$AO,MATCH($A10,Cables!$A:$A,0)))) -> 42 | I10: =IF($A10="","",IF(INDEX(Cables!$AP:$AP,MATCH($A10,Cables!$A:$A,0))="","",INDEX(Cables!$AP:$AP,MATCH($A10,Cables!$A:$A,0)))) -> 10 | J10: =IF($A10="","",IF(J$5>2*$G10,"",EXP(FORECAST(LN(J$5),INDEX(Attenuation!$K:$K,($H10-1+MIN(MAX(IFERROR(MATCH(LN(J$5),INDEX(Attenuation!$J:$J,$H10):INDEX(Attenuation!$J:$J,$H10+$I10-1),1),1),1),$I10-1))):INDEX(Attenuation!$K:$K,($H10-1+MIN(MAX(IFERROR(MATCH(LN(J$5),INDEX(Attenuation!$J:$J,$H10):INDEX(Attenuation!$J:$J,$H10+$I10-1),1),1),1),$I10-1))+1),INDEX(Attenuation!$J:$J,($H10-1+MIN(MAX(IFERROR(MATCH(LN(J$5),INDEX(Attenuation!$J:$J,$H10):INDEX(Attenuation!$J:$J,$H10+$I10-1),1),1),1),$I10-1))):INDEX(Attenuation!$J:$J,($H10-1+MIN(MAX(IFERROR(MATCH(LN(J$5),INDEX(Attenuation!$J:$J,$H10):INDEX(Attenuation!$J:$J,$H10+$I10-1),1),1),1),$I10-1))+1))))) -> 2.920024 | K10: =IF($A10="","",IF(K$5>2*$G10,"",EXP(FORECAST(LN(K$5),INDEX(Attenuation!$K:$K,($H10-1+MIN(MAX(IFERROR(MATCH(LN(K$5),INDEX(Attenuation!$J:$J,$H10):INDEX(Attenuation!$J:$J,$H10+$I10-1),1),1),1),$I10-1))):INDEX(Attenuation!$K:$K,($H10-1+MIN(MAX(IFERROR(MATCH(LN(K$5),INDEX(Attenuation!$J:$J,$H10):INDEX(Attenuation!$J:$J,$H10+$I10-1),1),1),1),$I10-1))+1),INDEX(Attenuation!$J:$J,($H10-1+MIN(MAX(IFERROR(MATCH(LN(K$5),INDEX(Attenuation!$J:$J,$H10):INDEX(Attenuation!$J:$J,$H10+$I10-1),1),1),1),$I10-1))):INDEX(Attenuation!$J:$J,($H10-1+MIN(MAX(IFERROR(MATCH(LN(K$5),INDEX(Attenuation!$J:$J,$H10):INDEX(Attenuation!$J:$J,$H10+$I10-1),1),1),1),$I10-1))+1))))) -> 4.1404697 | L10: =IF($A10="","",IF(L$5>2*$G10,"",EXP(FORECAST(LN(L$5),INDEX(Attenuation!$K:$K,($H10-1+MIN(MAX(IFERROR(MATCH(LN(L$5),INDEX(Attenuation!$J:$J,$H10):INDEX(Attenuation!$J:$J,$H10+$I10-1),1),1),1),$I10-1))):INDEX(Attenuation!$K:$K,($H10-1+MIN(MAX(IFERROR(MATCH(LN(L$5),INDEX(Attenuation!$J:$J,$H10):INDEX(Attenuation!$J:$J,$H10+$I10-1),1),1),1),$I10-1))+1),INDEX(Attenuation!$J:$J,($H10-1+MIN(MAX(IFERROR(MATCH(LN(L$5),INDEX(Attenuation!$J:$J,$H10):INDEX(Attenuation!$J:$J,$H10+$I10-1),1),1),1),$I10-1))):INDEX(Attenuation!$J:$J,($H10-1+MIN(MAX(IFERROR(MATCH(LN(L$5),INDEX(Attenuation!$J:$J,$H10):INDEX(Attenuation!$J:$J,$H10+$I10-1),1),1),1),$I10-1))+1))))) -> 5.958512 | M10: =IF($A10="","",IF(M$5>2*$G10,"",EXP(FORECAST(LN(M$5),INDEX(Attenuation!$K:$K,($H10-1+MIN(MAX(IFERROR(MATCH(LN(M$5),INDEX(Attenuation!$J:$J,$H10):INDEX(Attenuation!$J:$J,$H10+$I10-1),1),1),1),$I10-1))):INDEX(Attenuation!$K:$K,($H10-1+MIN(MAX(IFERROR(MATCH(LN(M$5),INDEX(Attenuation!$J:$J,$H10):INDEX(Attenuation!$J:$J,$H10+$I10-1),1),1),1),$I10-1))+1),INDEX(Attenuation!$J:$J,($H10-1+MIN(MAX(IFERROR(MATCH(LN(M$5),INDEX(Attenuation!$J:$J,$H10):INDEX(Attenuation!$J:$J,$H10+$I10-1),1),1),1),$I10-1))):INDEX(Attenuation!$J:$J,($H10-1+MIN(MAX(IFERROR(MATCH(LN(M$5),INDEX(Attenuation!$J:$J,$H10):INDEX(Attenuation!$J:$J,$H10+$I10-1),1),1),1),$I10-1))+1))))) -> 8.5748399 | N10: =IF($A10="","",IF(N$5>2*$G10,"",EXP(FORECAST(LN(N$5),INDEX(Attenuation!$K:$K,($H10-1+MIN(MAX(IFERROR(MATCH(LN(N$5),INDEX(Attenuation!$J:$J,$H10):INDEX(Attenuation!$J:$J,$H10+$I10-1),1),1),1),$I10-1))):INDEX(Attenuation!$K:$K,($H10-1+MIN(MAX(IFERROR(MATCH(LN(N$5),INDEX(Attenuation!$J:$J,$H10):INDEX(Attenuation!$J:$J,$H10+$I10-1),1),1),1),$I10-1))+1),INDEX(Attenuation!$J:$J,($H10-1+MIN(MAX(IFERROR(MATCH(LN(N$5),INDEX(Attenuation!$J:$J,$H10):INDEX(Attenuation!$J:$J,$H10+$I10-1),1),1),1),$I10-1))):INDEX(Attenuation!$J:$J,($H10-1+MIN(MAX(IFERROR(MATCH(LN(N$5),INDEX(Attenuation!$J:$J,$H10):INDEX(Attenuation!$J:$J,$H10+$I10-1),1),1),1),$I10-1))+1))))) -> 10.609666 | O10: =IF($A10="","",IF(O$5>2*$G10,"",EXP(FORECAST(LN(O$5),INDEX(Attenuation!$K:$K,($H10-1+MIN(MAX(IFERROR(MATCH(LN(O$5),INDEX(Attenuation!$J:$J,$H10):INDEX(Attenuation!$J:$J,$H10+$I10-1),1),1),1),$I10-1))):INDEX(Attenuation!$K:$K,($H10-1+MIN(MAX(IFERROR(MATCH(LN(O$5),INDEX(Attenuation!$J:$J,$H10):INDEX(Attenuation!$J:$J,$H10+$I10-1),1),1),1),$I10-1))+1),INDEX(Attenuation!$J:$J,($H10-1+MIN(MAX(IFERROR(MATCH(LN(O$5),INDEX(Attenuation!$J:$J,$H10):INDEX(Attenuation!$J:$J,$H10+$I10-1),1),1),1),$I10-1))):INDEX(Attenuation!$J:$J,($H10-1+MIN(MAX(IFERROR(MATCH(LN(O$5),INDEX(Attenuation!$J:$J,$H10):INDEX(Attenuation!$J:$J,$H10+$I10-1),1),1),1),$I10-1))+1))))) -> 12.339974 | P10: =IF($A10="","",IF(P$5>2*$G10,"",EXP(FORECAST(LN(P$5),INDEX(Attenuation!$K:$K,($H10-1+MIN(MAX(IFERROR(MATCH(LN(P$5),INDEX(Attenuation!$J:$J,$H10):INDEX(Attenuation!$J:$J,$H10+$I10-1),1),1),1),$I10-1))):INDEX(Attenuation!$K:$K,($H10-1+MIN(MAX(IFERROR(MATCH(LN(P$5),INDEX(Attenuation!$J:$J,$H10):INDEX(Attenuation!$J:$J,$H10+$I10-1),1),1),1),$I10-1))+1),INDEX(Attenuation!$J:$J,($H10-1+MIN(MAX(IFERROR(MATCH(LN(P$5),INDEX(Attenuation!$J:$J,$H10):INDEX(Attenuation!$J:$J,$H10+$I10-1),1),1),1),$I10-1))):INDEX(Attenuation!$J:$J,($H10-1+MIN(MAX(IFERROR(MATCH(LN(P$5),INDEX(Attenuation!$J:$J,$H10):INDEX(Attenuation!$J:$J,$H10+$I10-1),1),1),1),$I10-1))+1))))) -> 16.732283 | Q10: =IF($A10="","",IF(Q$5>2*$G10,"",EXP(FORECAST(LN(Q$5),INDEX(Attenuation!$K:$K,($H10-1+MIN(MAX(IFERROR(MATCH(LN(Q$5),INDEX(Attenuation!$J:$J,$H10):INDEX(Attenuation!$J:$J,$H10+$I10-1),1),1),1),$I10-1))):INDEX(Attenuation!$K:$K,($H10-1+MIN(MAX(IFERROR(MATCH(LN(Q$5),INDEX(Attenuation!$J:$J,$H10):INDEX(Attenuation!$J:$J,$H10+$I10-1),1),1),1),$I10-1))+1),INDEX(Attenuation!$J:$J,($H10-1+MIN(MAX(IFERROR(MATCH(LN(Q$5),INDEX(Attenuation!$J:$J,$H10):INDEX(Attenuation!$J:$J,$H10+$I10-1),1),1),1),$I10-1))):INDEX(Attenuation!$J:$J,($H10-1+MIN(MAX(IFERROR(MATCH(LN(Q$5),INDEX(Attenuation!$J:$J,$H10):INDEX(Attenuation!$J:$J,$H10+$I10-1),1),1),1),$I10-1))+1))))) -> 28.601549 | ... U10: =IF($A10="","",IF(U$5>2*$G10,"",EXP(FORECAST(LN(U$5),INDEX(Attenuation!$K:$K,($H10-1+MIN(MAX(IFERROR(MATCH(LN(U$5),INDEX(Attenuation!$J:$J,$H10):INDEX(Attenuation!$J:$J,$H10+$I10-1),1),1),1),$I10-1))):INDEX(Attenuation!$K:$K,($H10-1+MIN(MAX(IFERROR(MATCH(LN(U$5),INDEX(Attenuation!$J:$J,$H10):INDEX(Attenuation!$J:$J,$H10+$I10-1),1),1),1),$I10-1))+1),INDEX(Attenuation!$J:$J,($H10-1+MIN(MAX(IFERROR(MATCH(LN(U$5),INDEX(Attenuation!$J:$J,$H10):INDEX(Attenuation!$J:$J,$H10+$I10-1),1),1),1),$I10-1))):INDEX(Attenuation!$J:$J,($H10-1+MIN(MAX(IFERROR(MATCH(LN(U$5),INDEX(Attenuation!$J:$J,$H10):INDEX(Attenuation!$J:$J,$H10+$I10-1),1),1),1),$I10-1))+1))))) | W10: =IF(J10="","",J10*0.3048) -> 0.89002331 | X10: =IF(K10="","",K10*0.3048) -> 1.2620152 | Y10: =IF(L10="","",L10*0.3048) -> 1.8161544 | Z10: =IF(M10="","",M10*0.3048) -> 2.6136112 | AA10: =IF(N10="","",N10*0.3048) -> 3.2338261 | AB10: =IF(O10="","",O10*0.3048) -> 3.7612239 | AC10: =IF(P10="","",P10*0.3048) -> 5.1 | AD10: =IF(Q10="","",Q10*0.3048) -> 8.7177522 | ... AH10: =IF(U10="","",U10*0.3048)
A11: =IF(ROWS($A$6:A11)>COUNTA(Cables!$A:$A)-1,"",INDEX(Cables!$A:$A,ROWS($A$6:A11)+1)) -> BEL-8259 | B11: =IF($A11="","",IF(INDEX(Cables!$B:$B,MATCH($A11,Cables!$A:$A,0))="","",INDEX(Cables!$B:$B,MATCH($A11,Cables!$A:$A,0)))) -> Belden 8259 (RG-58) | C11: =IF($A11="","",IF(INDEX(Cables!$F:$F,MATCH($A11,Cables!$A:$A,0))="","",INDEX(Cables!$F:$F,MATCH($A11,Cables!$A:$A,0)))) -> 50 | D11: =IF($A11="","",IF(INDEX(Cables!$H:$H,MATCH($A11,Cables!$A:$A,0))="","",INDEX(Cables!$H:$H,MATCH($A11,Cables!$A:$A,0)))) -> 4.9 | E11: =IF($A11="","",IF(INDEX(Cables!$Q:$Q,MATCH($A11,Cables!$A:$A,0))="","",INDEX(Cables!$Q:$Q,MATCH($A11,Cables!$A:$A,0)))) -> 0.66 | F11: =IF($A11="","",IF(INDEX(Cables!$AQ:$AQ,MATCH($A11,Cables!$A:$A,0))="","",INDEX(Cables!$AQ:$AQ,MATCH($A11,Cables!$A:$A,0)))) -> 1 | G11: =IF($A11="","",IF(INDEX(Cables!$AR:$AR,MATCH($A11,Cables!$A:$A,0))="","",INDEX(Cables!$AR:$AR,MATCH($A11,Cables!$A:$A,0)))) -> 1000 | H11: =IF($A11="","",IF(INDEX(Cables!$AO:$AO,MATCH($A11,Cables!$A:$A,0))="","",INDEX(Cables!$AO:$AO,MATCH($A11,Cables!$A:$A,0)))) -> 52 | I11: =IF($A11="","",IF(INDEX(Cables!$AP:$AP,MATCH($A11,Cables!$A:$A,0))="","",INDEX(Cables!$AP:$AP,MATCH($A11,Cables!$A:$A,0)))) -> 9 | J11: =IF($A11="","",IF(J$5>2*$G11,"",EXP(FORECAST(LN(J$5),INDEX(Attenuation!$K:$K,($H11-1+MIN(MAX(IFERROR(MATCH(LN(J$5),INDEX(Attenuation!$J:$J,$H11):INDEX(Attenuation!$J:$J,$H11+$I11-1),1),1),1),$I11-1))):INDEX(Attenuation!$K:$K,($H11-1+MIN(MAX(IFERROR(MATCH(LN(J$5),INDEX(Attenuation!$J:$J,$H11):INDEX(Attenuation!$J:$J,$H11+$I11-1),1),1),1),$I11-1))+1),INDEX(Attenuation!$J:$J,($H11-1+MIN(MAX(IFERROR(MATCH(LN(J$5),INDEX(Attenuation!$J:$J,$H11):INDEX(Attenuation!$J:$J,$H11+$I11-1),1),1),1),$I11-1))):INDEX(Attenuation!$J:$J,($H11-1+MIN(MAX(IFERROR(MATCH(LN(J$5),INDEX(Attenuation!$J:$J,$H11):INDEX(Attenuation!$J:$J,$H11+$I11-1),1),1),1),$I11-1))+1))))) -> 1.8389903 | K11: =IF($A11="","",IF(K$5>2*$G11,"",EXP(FORECAST(LN(K$5),INDEX(Attenuation!$K:$K,($H11-1+MIN(MAX(IFERROR(MATCH(LN(K$5),INDEX(Attenuation!$J:$J,$H11):INDEX(Attenuation!$J:$J,$H11+$I11-1),1),1),1),$I11-1))):INDEX(Attenuation!$K:$K,($H11-1+MIN(MAX(IFERROR(MATCH(LN(K$5),INDEX(Attenuation!$J:$J,$H11):INDEX(Attenuation!$J:$J,$H11+$I11-1),1),1),1),$I11-1))+1),INDEX(Attenuation!$J:$J,($H11-1+MIN(MAX(IFERROR(MATCH(LN(K$5),INDEX(Attenuation!$J:$J,$H11):INDEX(Attenuation!$J:$J,$H11+$I11-1),1),1),1),$I11-1))):INDEX(Attenuation!$J:$J,($H11-1+MIN(MAX(IFERROR(MATCH(LN(K$5),INDEX(Attenuation!$J:$J,$H11):INDEX(Attenuation!$J:$J,$H11+$I11-1),1),1),1),$I11-1))+1))))) -> 2.6937488 | L11: =IF($A11="","",IF(L$5>2*$G11,"",EXP(FORECAST(LN(L$5),INDEX(Attenuation!$K:$K,($H11-1+MIN(MAX(IFERROR(MATCH(LN(L$5),INDEX(Attenuation!$J:$J,$H11):INDEX(Attenuation!$J:$J,$H11+$I11-1),1),1),1),$I11-1))):INDEX(Attenuation!$K:$K,($H11-1+MIN(MAX(IFERROR(MATCH(LN(L$5),INDEX(Attenuation!$J:$J,$H11):INDEX(Attenuation!$J:$J,$H11+$I11-1),1),1),1),$I11-1))+1),INDEX(Attenuation!$J:$J,($H11-1+MIN(MAX(IFERROR(MATCH(LN(L$5),INDEX(Attenuation!$J:$J,$H11):INDEX(Attenuation!$J:$J,$H11+$I11-1),1),1),1),$I11-1))):INDEX(Attenuation!$J:$J,($H11-1+MIN(MAX(IFERROR(MATCH(LN(L$5),INDEX(Attenuation!$J:$J,$H11):INDEX(Attenuation!$J:$J,$H11+$I11-1),1),1),1),$I11-1))+1))))) -> 4.0101233 | M11: =IF($A11="","",IF(M$5>2*$G11,"",EXP(FORECAST(LN(M$5),INDEX(Attenuation!$K:$K,($H11-1+MIN(MAX(IFERROR(MATCH(LN(M$5),INDEX(Attenuation!$J:$J,$H11):INDEX(Attenuation!$J:$J,$H11+$I11-1),1),1),1),$I11-1))):INDEX(Attenuation!$K:$K,($H11-1+MIN(MAX(IFERROR(MATCH(LN(M$5),INDEX(Attenuation!$J:$J,$H11):INDEX(Attenuation!$J:$J,$H11+$I11-1),1),1),1),$I11-1))+1),INDEX(Attenuation!$J:$J,($H11-1+MIN(MAX(IFERROR(MATCH(LN(M$5),INDEX(Attenuation!$J:$J,$H11):INDEX(Attenuation!$J:$J,$H11+$I11-1),1),1),1),$I11-1))):INDEX(Attenuation!$J:$J,($H11-1+MIN(MAX(IFERROR(MATCH(LN(M$5),INDEX(Attenuation!$J:$J,$H11):INDEX(Attenuation!$J:$J,$H11+$I11-1),1),1),1),$I11-1))+1))))) -> 5.9436288 | N11: =IF($A11="","",IF(N$5>2*$G11,"",EXP(FORECAST(LN(N$5),INDEX(Attenuation!$K:$K,($H11-1+MIN(MAX(IFERROR(MATCH(LN(N$5),INDEX(Attenuation!$J:$J,$H11):INDEX(Attenuation!$J:$J,$H11+$I11-1),1),1),1),$I11-1))):INDEX(Attenuation!$K:$K,($H11-1+MIN(MAX(IFERROR(MATCH(LN(N$5),INDEX(Attenuation!$J:$J,$H11):INDEX(Attenuation!$J:$J,$H11+$I11-1),1),1),1),$I11-1))+1),INDEX(Attenuation!$J:$J,($H11-1+MIN(MAX(IFERROR(MATCH(LN(N$5),INDEX(Attenuation!$J:$J,$H11):INDEX(Attenuation!$J:$J,$H11+$I11-1),1),1),1),$I11-1))):INDEX(Attenuation!$J:$J,($H11-1+MIN(MAX(IFERROR(MATCH(LN(N$5),INDEX(Attenuation!$J:$J,$H11):INDEX(Attenuation!$J:$J,$H11+$I11-1),1),1),1),$I11-1))+1))))) -> 7.461668 | O11: =IF($A11="","",IF(O$5>2*$G11,"",EXP(FORECAST(LN(O$5),INDEX(Attenuation!$K:$K,($H11-1+MIN(MAX(IFERROR(MATCH(LN(O$5),INDEX(Attenuation!$J:$J,$H11):INDEX(Attenuation!$J:$J,$H11+$I11-1),1),1),1),$I11-1))):INDEX(Attenuation!$K:$K,($H11-1+MIN(MAX(IFERROR(MATCH(LN(O$5),INDEX(Attenuation!$J:$J,$H11):INDEX(Attenuation!$J:$J,$H11+$I11-1),1),1),1),$I11-1))+1),INDEX(Attenuation!$J:$J,($H11-1+MIN(MAX(IFERROR(MATCH(LN(O$5),INDEX(Attenuation!$J:$J,$H11):INDEX(Attenuation!$J:$J,$H11+$I11-1),1),1),1),$I11-1))):INDEX(Attenuation!$J:$J,($H11-1+MIN(MAX(IFERROR(MATCH(LN(O$5),INDEX(Attenuation!$J:$J,$H11):INDEX(Attenuation!$J:$J,$H11+$I11-1),1),1),1),$I11-1))+1))))) -> 8.768483 | P11: =IF($A11="","",IF(P$5>2*$G11,"",EXP(FORECAST(LN(P$5),INDEX(Attenuation!$K:$K,($H11-1+MIN(MAX(IFERROR(MATCH(LN(P$5),INDEX(Attenuation!$J:$J,$H11):INDEX(Attenuation!$J:$J,$H11+$I11-1),1),1),1),$I11-1))):INDEX(Attenuation!$K:$K,($H11-1+MIN(MAX(IFERROR(MATCH(LN(P$5),INDEX(Attenuation!$J:$J,$H11):INDEX(Attenuation!$J:$J,$H11+$I11-1),1),1),1),$I11-1))+1),INDEX(Attenuation!$J:$J,($H11-1+MIN(MAX(IFERROR(MATCH(LN(P$5),INDEX(Attenuation!$J:$J,$H11):INDEX(Attenuation!$J:$J,$H11+$I11-1),1),1),1),$I11-1))):INDEX(Attenuation!$J:$J,($H11-1+MIN(MAX(IFERROR(MATCH(LN(P$5),INDEX(Attenuation!$J:$J,$H11):INDEX(Attenuation!$J:$J,$H11+$I11-1),1),1),1),$I11-1))+1))))) -> 12.139108 | Q11: =IF($A11="","",IF(Q$5>2*$G11,"",EXP(FORECAST(LN(Q$5),INDEX(Attenuation!$K:$K,($H11-1+MIN(MAX(IFERROR(MATCH(LN(Q$5),INDEX(Attenuation!$J:$J,$H11):INDEX(Attenuation!$J:$J,$H11+$I11-1),1),1),1),$I11-1))):INDEX(Attenuation!$K:$K,($H11-1+MIN(MAX(IFERROR(MATCH(LN(Q$5),INDEX(Attenuation!$J:$J,$H11):INDEX(Attenuation!$J:$J,$H11+$I11-1),1),1),1),$I11-1))+1),INDEX(Attenuation!$J:$J,($H11-1+MIN(MAX(IFERROR(MATCH(LN(Q$5),INDEX(Attenuation!$J:$J,$H11):INDEX(Attenuation!$J:$J,$H11+$I11-1),1),1),1),$I11-1))):INDEX(Attenuation!$J:$J,($H11-1+MIN(MAX(IFERROR(MATCH(LN(Q$5),INDEX(Attenuation!$J:$J,$H11):INDEX(Attenuation!$J:$J,$H11+$I11-1),1),1),1),$I11-1))+1))))) -> 21.928803 | ... U11: =IF($A11="","",IF(U$5>2*$G11,"",EXP(FORECAST(LN(U$5),INDEX(Attenuation!$K:$K,($H11-1+MIN(MAX(IFERROR(MATCH(LN(U$5),INDEX(Attenuation!$J:$J,$H11):INDEX(Attenuation!$J:$J,$H11+$I11-1),1),1),1),$I11-1))):INDEX(Attenuation!$K:$K,($H11-1+MIN(MAX(IFERROR(MATCH(LN(U$5),INDEX(Attenuation!$J:$J,$H11):INDEX(Attenuation!$J:$J,$H11+$I11-1),1),1),1),$I11-1))+1),INDEX(Attenuation!$J:$J,($H11-1+MIN(MAX(IFERROR(MATCH(LN(U$5),INDEX(Attenuation!$J:$J,$H11):INDEX(Attenuation!$J:$J,$H11+$I11-1),1),1),1),$I11-1))):INDEX(Attenuation!$J:$J,($H11-1+MIN(MAX(IFERROR(MATCH(LN(U$5),INDEX(Attenuation!$J:$J,$H11):INDEX(Attenuation!$J:$J,$H11+$I11-1),1),1),1),$I11-1))+1))))) | W11: =IF(J11="","",J11*0.3048) -> 0.56052423 | X11: =IF(K11="","",K11*0.3048) -> 0.82105464 | Y11: =IF(L11="","",L11*0.3048) -> 1.2222856 | Z11: =IF(M11="","",M11*0.3048) -> 1.8116181 | AA11: =IF(N11="","",N11*0.3048) -> 2.2743164 | AB11: =IF(O11="","",O11*0.3048) -> 2.6726336 | AC11: =IF(P11="","",P11*0.3048) -> 3.7 | AD11: =IF(Q11="","",Q11*0.3048) -> 6.683899 | ... AH11: =IF(U11="","",U11*0.3048)
A12: =IF(ROWS($A$6:A12)>COUNTA(Cables!$A:$A)-1,"",INDEX(Cables!$A:$A,ROWS($A$6:A12)+1)) -> MP-RG58CU | B12: =IF($A12="","",IF(INDEX(Cables!$B:$B,MATCH($A12,Cables!$A:$A,0))="","",INDEX(Cables!$B:$B,MATCH($A12,Cables!$A:$A,0)))) -> Messi & Paoloni RG 58 C/U | C12: =IF($A12="","",IF(INDEX(Cables!$F:$F,MATCH($A12,Cables!$A:$A,0))="","",INDEX(Cables!$F:$F,MATCH($A12,Cables!$A:$A,0)))) -> 50 | D12: =IF($A12="","",IF(INDEX(Cables!$H:$H,MATCH($A12,Cables!$A:$A,0))="","",INDEX(Cables!$H:$H,MATCH($A12,Cables!$A:$A,0)))) -> 5 | E12: =IF($A12="","",IF(INDEX(Cables!$Q:$Q,MATCH($A12,Cables!$A:$A,0))="","",INDEX(Cables!$Q:$Q,MATCH($A12,Cables!$A:$A,0)))) | F12: =IF($A12="","",IF(INDEX(Cables!$AQ:$AQ,MATCH($A12,Cables!$A:$A,0))="","",INDEX(Cables!$AQ:$AQ,MATCH($A12,Cables!$A:$A,0)))) -> 10 | G12: =IF($A12="","",IF(INDEX(Cables!$AR:$AR,MATCH($A12,Cables!$A:$A,0))="","",INDEX(Cables!$AR:$AR,MATCH($A12,Cables!$A:$A,0)))) -> 1296 | H12: =IF($A12="","",IF(INDEX(Cables!$AO:$AO,MATCH($A12,Cables!$A:$A,0))="","",INDEX(Cables!$AO:$AO,MATCH($A12,Cables!$A:$A,0)))) -> 61 | I12: =IF($A12="","",IF(INDEX(Cables!$AP:$AP,MATCH($A12,Cables!$A:$A,0))="","",INDEX(Cables!$AP:$AP,MATCH($A12,Cables!$A:$A,0)))) -> 9 | J12: =IF($A12="","",IF(J$5>2*$G12,"",EXP(FORECAST(LN(J$5),INDEX(Attenuation!$K:$K,($H12-1+MIN(MAX(IFERROR(MATCH(LN(J$5),INDEX(Attenuation!$J:$J,$H12):INDEX(Attenuation!$J:$J,$H12+$I12-1),1),1),1),$I12-1))):INDEX(Attenuation!$K:$K,($H12-1+MIN(MAX(IFERROR(MATCH(LN(J$5),INDEX(Attenuation!$J:$J,$H12):INDEX(Attenuation!$J:$J,$H12+$I12-1),1),1),1),$I12-1))+1),INDEX(Attenuation!$J:$J,($H12-1+MIN(MAX(IFERROR(MATCH(LN(J$5),INDEX(Attenuation!$J:$J,$H12):INDEX(Attenuation!$J:$J,$H12+$I12-1),1),1),1),$I12-1))):INDEX(Attenuation!$J:$J,($H12-1+MIN(MAX(IFERROR(MATCH(LN(J$5),INDEX(Attenuation!$J:$J,$H12):INDEX(Attenuation!$J:$J,$H12+$I12-1),1),1),1),$I12-1))+1))))) -> 1.9791836 | K12: =IF($A12="","",IF(K$5>2*$G12,"",EXP(FORECAST(LN(K$5),INDEX(Attenuation!$K:$K,($H12-1+MIN(MAX(IFERROR(MATCH(LN(K$5),INDEX(Attenuation!$J:$J,$H12):INDEX(Attenuation!$J:$J,$H12+$I12-1),1),1),1),$I12-1))):INDEX(Attenuation!$K:$K,($H12-1+MIN(MAX(IFERROR(MATCH(LN(K$5),INDEX(Attenuation!$J:$J,$H12):INDEX(Attenuation!$J:$J,$H12+$I12-1),1),1),1),$I12-1))+1),INDEX(Attenuation!$J:$J,($H12-1+MIN(MAX(IFERROR(MATCH(LN(K$5),INDEX(Attenuation!$J:$J,$H12):INDEX(Attenuation!$J:$J,$H12+$I12-1),1),1),1),$I12-1))):INDEX(Attenuation!$J:$J,($H12-1+MIN(MAX(IFERROR(MATCH(LN(K$5),INDEX(Attenuation!$J:$J,$H12):INDEX(Attenuation!$J:$J,$H12+$I12-1),1),1),1),$I12-1))+1))))) -> 2.7678554 | L12: =IF($A12="","",IF(L$5>2*$G12,"",EXP(FORECAST(LN(L$5),INDEX(Attenuation!$K:$K,($H12-1+MIN(MAX(IFERROR(MATCH(LN(L$5),INDEX(Attenuation!$J:$J,$H12):INDEX(Attenuation!$J:$J,$H12+$I12-1),1),1),1),$I12-1))):INDEX(Attenuation!$K:$K,($H12-1+MIN(MAX(IFERROR(MATCH(LN(L$5),INDEX(Attenuation!$J:$J,$H12):INDEX(Attenuation!$J:$J,$H12+$I12-1),1),1),1),$I12-1))+1),INDEX(Attenuation!$J:$J,($H12-1+MIN(MAX(IFERROR(MATCH(LN(L$5),INDEX(Attenuation!$J:$J,$H12):INDEX(Attenuation!$J:$J,$H12+$I12-1),1),1),1),$I12-1))):INDEX(Attenuation!$J:$J,($H12-1+MIN(MAX(IFERROR(MATCH(LN(L$5),INDEX(Attenuation!$J:$J,$H12):INDEX(Attenuation!$J:$J,$H12+$I12-1),1),1),1),$I12-1))+1))))) -> 3.9261898 | M12: =IF($A12="","",IF(M$5>2*$G12,"",EXP(FORECAST(LN(M$5),INDEX(Attenuation!$K:$K,($H12-1+MIN(MAX(IFERROR(MATCH(LN(M$5),INDEX(Attenuation!$J:$J,$H12):INDEX(Attenuation!$J:$J,$H12+$I12-1),1),1),1),$I12-1))):INDEX(Attenuation!$K:$K,($H12-1+MIN(MAX(IFERROR(MATCH(LN(M$5),INDEX(Attenuation!$J:$J,$H12):INDEX(Attenuation!$J:$J,$H12+$I12-1),1),1),1),$I12-1))+1),INDEX(Attenuation!$J:$J,($H12-1+MIN(MAX(IFERROR(MATCH(LN(M$5),INDEX(Attenuation!$J:$J,$H12):INDEX(Attenuation!$J:$J,$H12+$I12-1),1),1),1),$I12-1))):INDEX(Attenuation!$J:$J,($H12-1+MIN(MAX(IFERROR(MATCH(LN(M$5),INDEX(Attenuation!$J:$J,$H12):INDEX(Attenuation!$J:$J,$H12+$I12-1),1),1),1),$I12-1))+1))))) -> 5.5692818 | N12: =IF($A12="","",IF(N$5>2*$G12,"",EXP(FORECAST(LN(N$5),INDEX(Attenuation!$K:$K,($H12-1+MIN(MAX(IFERROR(MATCH(LN(N$5),INDEX(Attenuation!$J:$J,$H12):INDEX(Attenuation!$J:$J,$H12+$I12-1),1),1),1),$I12-1))):INDEX(Attenuation!$K:$K,($H12-1+MIN(MAX(IFERROR(MATCH(LN(N$5),INDEX(Attenuation!$J:$J,$H12):INDEX(Attenuation!$J:$J,$H12+$I12-1),1),1),1),$I12-1))+1),INDEX(Attenuation!$J:$J,($H12-1+MIN(MAX(IFERROR(MATCH(LN(N$5),INDEX(Attenuation!$J:$J,$H12):INDEX(Attenuation!$J:$J,$H12+$I12-1),1),1),1),$I12-1))):INDEX(Attenuation!$J:$J,($H12-1+MIN(MAX(IFERROR(MATCH(LN(N$5),INDEX(Attenuation!$J:$J,$H12):INDEX(Attenuation!$J:$J,$H12+$I12-1),1),1),1),$I12-1))+1))))) -> 6.833022 | O12: =IF($A12="","",IF(O$5>2*$G12,"",EXP(FORECAST(LN(O$5),INDEX(Attenuation!$K:$K,($H12-1+MIN(MAX(IFERROR(MATCH(LN(O$5),INDEX(Attenuation!$J:$J,$H12):INDEX(Attenuation!$J:$J,$H12+$I12-1),1),1),1),$I12-1))):INDEX(Attenuation!$K:$K,($H12-1+MIN(MAX(IFERROR(MATCH(LN(O$5),INDEX(Attenuation!$J:$J,$H12):INDEX(Attenuation!$J:$J,$H12+$I12-1),1),1),1),$I12-1))+1),INDEX(Attenuation!$J:$J,($H12-1+MIN(MAX(IFERROR(MATCH(LN(O$5),INDEX(Attenuation!$J:$J,$H12):INDEX(Attenuation!$J:$J,$H12+$I12-1),1),1),1),$I12-1))):INDEX(Attenuation!$J:$J,($H12-1+MIN(MAX(IFERROR(MATCH(LN(O$5),INDEX(Attenuation!$J:$J,$H12):INDEX(Attenuation!$J:$J,$H12+$I12-1),1),1),1),$I12-1))+1))))) -> 7.9 | P12: =IF($A12="","",IF(P$5>2*$G12,"",EXP(FORECAST(LN(P$5),INDEX(Attenuation!$K:$K,($H12-1+MIN(MAX(IFERROR(MATCH(LN(P$5),INDEX(Attenuation!$J:$J,$H12):INDEX(Attenuation!$J:$J,$H12+$I12-1),1),1),1),$I12-1))):INDEX(Attenuation!$K:$K,($H12-1+MIN(MAX(IFERROR(MATCH(LN(P$5),INDEX(Attenuation!$J:$J,$H12):INDEX(Attenuation!$J:$J,$H12+$I12-1),1),1),1),$I12-1))+1),INDEX(Attenuation!$J:$J,($H12-1+MIN(MAX(IFERROR(MATCH(LN(P$5),INDEX(Attenuation!$J:$J,$H12):INDEX(Attenuation!$J:$J,$H12+$I12-1),1),1),1),$I12-1))):INDEX(Attenuation!$J:$J,($H12-1+MIN(MAX(IFERROR(MATCH(LN(P$5),INDEX(Attenuation!$J:$J,$H12):INDEX(Attenuation!$J:$J,$H12+$I12-1),1),1),1),$I12-1))+1))))) -> 10.8 | Q12: =IF($A12="","",IF(Q$5>2*$G12,"",EXP(FORECAST(LN(Q$5),INDEX(Attenuation!$K:$K,($H12-1+MIN(MAX(IFERROR(MATCH(LN(Q$5),INDEX(Attenuation!$J:$J,$H12):INDEX(Attenuation!$J:$J,$H12+$I12-1),1),1),1),$I12-1))):INDEX(Attenuation!$K:$K,($H12-1+MIN(MAX(IFERROR(MATCH(LN(Q$5),INDEX(Attenuation!$J:$J,$H12):INDEX(Attenuation!$J:$J,$H12+$I12-1),1),1),1),$I12-1))+1),INDEX(Attenuation!$J:$J,($H12-1+MIN(MAX(IFERROR(MATCH(LN(Q$5),INDEX(Attenuation!$J:$J,$H12):INDEX(Attenuation!$J:$J,$H12+$I12-1),1),1),1),$I12-1))):INDEX(Attenuation!$J:$J,($H12-1+MIN(MAX(IFERROR(MATCH(LN(Q$5),INDEX(Attenuation!$J:$J,$H12):INDEX(Attenuation!$J:$J,$H12+$I12-1),1),1),1),$I12-1))+1))))) -> 19.3 | ... U12: =IF($A12="","",IF(U$5>2*$G12,"",EXP(FORECAST(LN(U$5),INDEX(Attenuation!$K:$K,($H12-1+MIN(MAX(IFERROR(MATCH(LN(U$5),INDEX(Attenuation!$J:$J,$H12):INDEX(Attenuation!$J:$J,$H12+$I12-1),1),1),1),$I12-1))):INDEX(Attenuation!$K:$K,($H12-1+MIN(MAX(IFERROR(MATCH(LN(U$5),INDEX(Attenuation!$J:$J,$H12):INDEX(Attenuation!$J:$J,$H12+$I12-1),1),1),1),$I12-1))+1),INDEX(Attenuation!$J:$J,($H12-1+MIN(MAX(IFERROR(MATCH(LN(U$5),INDEX(Attenuation!$J:$J,$H12):INDEX(Attenuation!$J:$J,$H12+$I12-1),1),1),1),$I12-1))):INDEX(Attenuation!$J:$J,($H12-1+MIN(MAX(IFERROR(MATCH(LN(U$5),INDEX(Attenuation!$J:$J,$H12):INDEX(Attenuation!$J:$J,$H12+$I12-1),1),1),1),$I12-1))+1))))) | W12: =IF(J12="","",J12*0.3048) -> 0.60325516 | X12: =IF(K12="","",K12*0.3048) -> 0.84364232 | Y12: =IF(L12="","",L12*0.3048) -> 1.1967027 | Z12: =IF(M12="","",M12*0.3048) -> 1.6975171 | AA12: =IF(N12="","",N12*0.3048) -> 2.0827051 | AB12: =IF(O12="","",O12*0.3048) -> 2.40792 | AC12: =IF(P12="","",P12*0.3048) -> 3.29184 | AD12: =IF(Q12="","",Q12*0.3048) -> 5.88264 | ... AH12: =IF(U12="","",U12*0.3048)
